Workbook

Sheet All_India_Index_Upto_April23 (1
AE1: Broader Categories
A2: Sector | B2: Year | C2: Month | D2: Cereals and products | E2: Meat and fish | F2: Egg | G2: Milk and products | H2: Oils and fats | I2: Fruits | J2: Vegetables | K2: Pulses and products | L2: Sugar and Confectionery | M2: Spices | N2: Non-alcoholic beverages | O2: Prepared meals, snacks, sweets etc. | P2: Food and beverages | Q2: Pan, tobacco and intoxicants | R2: Clothing | S2: Footwear | T2: Clothing and footwear | U2: Housing | V2: Fuel and light | W2: Household goods and services | X2: Health | Y2: Transport and communication | Z2: Recreation and amusement | AA2: Education | AB2: Personal care and effects | AC2: Miscellaneous | AD2: General index | AE2: Food | AF2: Energy | AG2: Transportation | AH2: Education | AI2: Others
A3: Rural | B3: 2013 | C3: January | D3: 107.5 | E3: 106.3 | F3: 108.1 | G3: 104.9 | H3: 106.1 | I3: 103.9 | J3: 101.9 | K3: 106.1 | L3: 106.8 | M3: 103.1 | N3: 104.8 | O3: 106.7 | P3: 105.5 | Q3: 105.1 | R3: 106.5 | S3: 105.8 | T3: 106.4 | U3: 100.3 | V3: 105.5 | W3: 104.8 | X3: 104 | Y3: 103.3 | Z3: 103.4 | AA3: 103.8 | AB3: 104.7 | AC3: 104 | AD3: 105.1 | AE3: =SUM(D3:P3) -> 1371.7 | AF3: =SUM(V3) -> 105.5 | AG3: =SUM(Y3) -> 103.3 | AH3: =SUM(AA3) -> 103.8 | AI3: =SUM(Q3:U3,W3:X3,Z3,AB3:AC3) -> 1045
A4: Urban | B4: 2013 | C4: January | D4: 110.5 | E4: 109.1 | F4: 113 | G4: 103.6 | H4: 103.4 | I4: 102.3 | J4: 102.9 | K4: 105.8 | L4: 105.1 | M4: 101.8 | N4: 105.1 | O4: 107.9 | P4: 105.9 | Q4: 105.2 | R4: 105.9 | S4: 105 | T4: 105.8 | U4: 100.3 | V4: 105.4 | W4: 104.8 | X4: 104.1 | Y4: 103.2 | Z4: 102.9 | AA4: 103.5 | AB4: 104.3 | AC4: 103.7 | AD4: 104 | AE4: =SUM(D4:P4) -> 1376.4 | AF4: =SUM(V4) -> 105.4 | AG4: =SUM(Y4) -> 103.2 | AH4: =SUM(AA4) -> 103.5 | AI4: =SUM(Q4:U4,W4:X4,Z4,AB4:AC4) -> 1042
A5: Rural+Urban | B5: 2013 | C5: January | D5: 108.4 | E5: 107.3 | F5: 110 | G5: 104.4 | H5: 105.1 | I5: 103.2 | J5: 102.2 | K5: 106 | L5: 106.2 | M5: 102.7 | N5: 104.9 | O5: 107.3 | P5: 105.6 | Q5: 105.1 | R5: 106.3 | S5: 105.5 | T5: 106.2 | U5: 100.3 | V5: 105.5 | W5: 104.8 | X5: 104 | Y5: 103.2 | Z5: 103.1 | AA5: 103.6 | AB5: 104.5 | AC5: 103.9 | AD5: 104.6 | AE5: =SUM(D5:P5) -> 1373.3 | AF5: =SUM(V5) -> 105.5 | AG5: =SUM(Y5) -> 103.2 | AH5: =SUM(AA5) -> 103.6 | AI5: =SUM(Q5:U5,W5:X5,Z5,AB5:AC5) -> 1043.7
A6: Rural | B6: 2013 | C6: February | D6: 109.2 | E6: 108.7 | F6: 110.2 | G6: 105.4 | H6: 106.7 | I6: 104 | J6: 102.4 | K6: 105.9 | L6: 105.7 | M6: 103.1 | N6: 105.1 | O6: 107.7 | P6: 106.3 | Q6: 105.6 | R6: 107.1 | S6: 106.3 | T6: 107 | U6: 100.4 | V6: 106.2 | W6: 105.2 | X6: 104.4 | Y6: 103.9 | Z6: 104 | AA6: 104.1 | AB6: 104.6 | AC6: 104.4 | AD6: 105.8 | AE6: =SUM(D6:P6) -> 1380.4 | AF6: =SUM(V6) -> 106.2 | AG6: =SUM(Y6) -> 103.9 | AH6: =SUM(AA6) -> 104.1 | AI6: =SUM(Q6:U6,W6:X6,Z6,AB6:AC6) -> 1049
A7: Urban | B7: 2013 | C7: February | D7: 112.9 | E7: 112.9 | F7: 116.9 | G7: 104 | H7: 103.5 | I7: 103.1 | J7: 104.9 | K7: 104.1 | L7: 103.8 | M7: 102.3 | N7: 106 | O7: 109 | P7: 107.2 | Q7: 106 | R7: 106.6 | S7: 105.5 | T7: 106.4 | U7: 100.4 | V7: 105.7 | W7: 105.2 | X7: 104.7 | Y7: 104.4 | Z7: 103.3 | AA7: 103.7 | AB7: 104.3 | AC7: 104.3 | AD7: 104.7 | AE7: =SUM(D7:P7) -> 1390.6 | AF7: =SUM(V7) -> 105.7 | AG7: =SUM(Y7) -> 104.4 | AH7: =SUM(AA7) -> 103.7 | AI7: =SUM(Q7:U7,W7:X7,Z7,AB7:AC7) -> 1046.7
A8: Rural+Urban | B8: 2013 | C8: February | D8: 110.4 | E8: 110.2 | F8: 112.8 | G8: 104.9 | H8: 105.5 | I8: 103.6 | J8: 103.2 | K8: 105.3 | L8: 105.1 | M8: 102.8 | N8: 105.5 | O8: 108.3 | P8: 106.6 | Q8: 105.7 | R8: 106.9 | S8: 106 | T8: 106.8 | U8: 100.4 | V8: 106 | W8: 105.2 | X8: 104.5 | Y8: 104.2 | Z8: 103.6 | AA8: 103.9 | AB8: 104.5 | AC8: 104.4 | AD8: 105.3 | AE8: =SUM(D8:P8) -> 1384.2 | AF8: =SUM(V8) -> 106 | AG8: =SUM(Y8) -> 104.2 | AH8: =SUM(AA8) -> 103.9 | AI8: =SUM(Q8:U8,W8:X8,Z8,AB8:AC8) -> 1048
A9: Rural | B9: 2013 | C9: March | D9: 110.2 | E9: 108.8 | F9: 109.9 | G9: 105.6 | H9: 106.2 | I9: 105.7 | J9: 101.4 | K9: 105.7 | L9: 105 | M9: 103.3 | N9: 105.6 | O9: 108.2 | P9: 106.6 | Q9: 106.5 | R9: 107.6 | S9: 106.8 | T9: 107.5 | U9: 100.4 | V9: 106.1 | W9: 105.6 | X9: 104.7 | Y9: 104.6 | Z9: 104 | AA9: 104.3 | AB9: 104.3 | AC9: 104.6 | AD9: 106 | AE9: =SUM(D9:P9) -> 1382.2 | AF9: =SUM(V9) -> 106.1 | AG9: =SUM(Y9) -> 104.6 | AH9: =SUM(AA9) -> 104.3 | AI9: =SUM(Q9:U9,W9:X9,Z9,AB9:AC9) -> 1052
A10: Urban | B10: 2013 | C10: March | D10: 113.9 | E10: 111.4 | F10: 113.2 | G10: 104.3 | H10: 102.7 | I10: 104.9 | J10: 103.8 | K10: 103.5 | L10: 102.6 | M10: 102.4 | N10: 107 | O10: 109.8 | P10: 107.3 | Q10: 106.8 | R10: 107.2 | S10: 106 | T10: 107 | U10: 100.4 | V10: 106 | W10: 105.7 | X10: 105.2 | Y10: 105.5 | Z10: 103.5 | AA10: 103.8 | AB10: 104.2 | AC10: 104.9 | AD10: 105 | AE10: =SUM(D10:P10) -> 1386.8 | AF10: =SUM(V10) -> 106 | AG10: =SUM(Y10) -> 105.5 | AH10: =SUM(AA10) -> 103.8 | AI10: =SUM(Q10:U10,W10:X10,Z10,AB10:AC10) -> 1050.9
A11: Rural+Urban | B11: 2013 | C11: March | D11: 111.4 | E11: 109.7 | F11: 111.2 | G11: 105.1 | H11: 104.9 | I11: 105.3 | J11: 102.2 | K11: 105 | L11: 104.2 | M11: 103 | N11: 106.2 | O11: 108.9 | P11: 106.9 | Q11: 106.6 | R11: 107.4 | S11: 106.5 | T11: 107.3 | U11: 100.4 | V11: 106.1 | W11: 105.6 | X11: 104.9 | Y11: 105.1 | Z11: 103.7 | AA11: 104 | AB11: 104.3 | AC11: 104.7 | AD11: 105.5 | AE11: =SUM(D11:P11) -> 1384 | AF11: =SUM(V11) -> 106.1 | AG11: =SUM(Y11) -> 105.1 | AH11: =SUM(AA11) -> 104 | AI11: =SUM(Q11:U11,W11:X11,Z11,AB11:AC11) -> 1051.4
A12: Rural | B12: 2013 | C12: April | D12: 110.2 | E12: 109.5 | F12: 106.9 | G12: 106.3 | H12: 105.7 | I12: 108.3 | J12: 103.4 | K12: 105.7 | L12: 104.2 | M12: 103.2 | N12: 106.5 | O12: 108.8 | P12: 107.1 | Q12: 107.1 | R12: 108.1 | S12: 107.4 | T12: 108 | U12: 100.5 | V12: 106.5 | W12: 106.1 | X12: 105.1 | Y12: 104.4 | Z12: 104.5 | AA12: 104.8 | AB12: 102.7 | AC12: 104.6 | AD12: 106.4 | AE12: =SUM(D12:P12) -> 1385.8 | AF12: =SUM(V12) -> 106.5 | AG12: =SUM(Y12) -> 104.4 | AH12: =SUM(AA12) -> 104.8 | AI12: =SUM(Q12:U12,W12:X12,Z12,AB12:AC12) -> 1054.1
A13: Urban | B13: 2013 | C13: April | D13: 114.6 | E13: 113.4 | F13: 106 | G13: 104.7 | H13: 102.1 | I13: 109.5 | J13: 109.7 | K13: 104.6 | L13: 102 | M13: 103.5 | N13: 108.2 | O13: 110.6 | P13: 108.8 | Q13: 108.5 | R13: 107.9 | S13: 106.4 | T13: 107.7 | U13: 100.5 | V13: 106.4 | W13: 106.5 | X13: 105.7 | Y13: 105 | Z13: 104 | AA13: 105.2 | AB13: 103.2 | AC13: 105.1 | AD13: 105.7 | AE13: =SUM(D13:P13) -> 1397.7 | AF13: =SUM(V13) -> 106.4 | AG13: =SUM(Y13) -> 105 | AH13: =SUM(AA13) -> 105.2 | AI13: =SUM(Q13:U13,W13:X13,Z13,AB13:AC13) -> 1055.5
A14: Rural+Urban | B14: 2013 | C14: April | D14: 111.6 | E14: 110.9 | F14: 106.6 | G14: 105.7 | H14: 104.4 | I14: 108.9 | J14: 105.5 | K14: 105.3 | L14: 103.5 | M14: 103.3 | N14: 107.2 | O14: 109.6 | P14: 107.7 | Q14: 107.5 | R14: 108 | S14: 107 | T14: 107.9 | U14: 100.5 | V14: 106.5 | W14: 106.3 | X14: 105.3 | Y14: 104.7 | Z14: 104.2 | AA14: 105 | AB14: 102.9 | AC14: 104.8 | AD14: 106.1 | AE14: =SUM(D14:P14) -> 1390.2 | AF14: =SUM(V14) -> 106.5 | AG14: =SUM(Y14) -> 104.7 | AH14: =SUM(AA14) -> 105 | AI14: =SUM(Q14:U14,W14:X14,Z14,AB14:AC14) -> 1054.4
... A374: Rural+Urban | B374: 2023 | C374: May | D374: 173.7 | E374: 214.3 | F374: 173.2 | G374: 179.5 | H374: 170 | I374: 172.2 | J374: 161 | K374: 175.6 | L374: 122.7 | M374: 218 | N374: 173.4 | O374: 194.2 | P374: 179.1 | Q374: 201 | R374: 187.3 | S374: 179.7 | T374: 186.2 | U374: 175.6 | V374: 182.8 | W374: 175.2 | X374: 185.7 | Y374: 164.8 | Z374: 171.2 | AA374: 177.1 | AB374: 185.2 | AC374: 175.7 | AD374: 179.1 | AE374: =SUM(D374:P374) -> 2306.9 | AF374: =SUM(V374) -> 182.8 | AG374: =SUM(Y374) -> 164.8 | AH374: =SUM(AA374) -> 177.1 | AI374: =SUM(Q374:U374,W374:X374,Z374,AB374:AC374) -> 1822.8

Sheet Sheet4
A1: Sector | B1: Rural+Urban
A3: Row Labels | B3: Average of General index
A4: 2013 | B4: 110.03333
A5: 2014 | B5: 117.35
A6: 2015 | B6: 123.10833
A7: 2016 | B7: 129.2
A8: 2017 | B8: 133.5
A9: 2018 | B9: 138.775
A10: 2019 | B10: 144.18182
A11: 2020 | B11: 152.58333
A12: 2021 | B12: 161.45833
A13: 2022 | B13: 172.15
A14: 2023 | B14: 177.62
A15: Grand Total | B15: 139.77419
A17: Year | B17: CPI | C17: % YOY
A18: 2013 | B18: 1446.3917 | C18: 0
A19: 2014 | B19: 1542.0833 | C19: =(B19-B18)/B18*100 -> 6.615889
A20: 2015 | B20: 1624.425 | C20: =(B20-B19)/B19*100 -> 5.3396379
A21: 2016 | B21: 1735.8083 | C21: =(B21-B20)/B20*100 -> 6.8567852
A22: 2017 | B22: 1753.9417 | C22: =(B22-B21)/B21*100 -> 1.0446622
A23: 2018 | B23: 1772.9583 | C23: =(B23-B22)/B22*100 -> 1.0842246
A24: 2019 | B24: 1833.0636 | C24: =(B24-B23)/B23*100 -> 3.3901137
A25: 2020 | B25: 1986.2583 | C25: =(B25-B24)/B24*100 -> 8.3573038
A26: 2021 | B26: 2120.0333 | C26: =(B26-B25)/B25*100 -> 6.7350252
A27: 2022 | B27: 2243.2167 | C27: =(B27-B26)/B26*100 -> 5.8104432
A28: 2023 | B28: 2289.5 | C28: =(B28-B27)/B27*100 -> 2.0632574
A29: Grand Total | B29: 1825.1016
A32: Year | B32: CPI | C32: % YOY
A33: 2013 | B33: 108.63333 | C33: 0
A34: 2014 | B34: 113.61667 | C34: =(B34-B33)/B33*100 -> 4.5872967
A35: 2015 | B35: 119.64167 | C35: =(B35-B34)/B34*100 -> 5.3029192
A36: 2016 | B36: 123.625 | C36: =(B36-B35)/B35*100 -> 3.3293864
A37: 2017 | B37: 130.50833 | C37: =(B37-B36)/B36*100 -> 5.5679137
A38: 2018 | B38: 139.775 | C38: =(B38-B37)/B37*100 -> 7.1004406
A39: 2019 | B39: 140.24545 | C39: =(B39-B38)/B38*100 -> 0.33657989
A40: 2020 | B40: 144.15833 | C40: =(B40-B39)/B39*100 -> 2.7900218
A41: 2021 | B41: 159.05833 | C41: =(B41-B40)/B40*100 -> 10.335858
A42: 2022 | B42: 175.13333 | C42: =(B42-B41)/B41*100 -> 10.106355
A43: 2023 | B43: 182.1 | C43: =(B43-B42)/B42*100 -> 3.9779216
A44: Grand Total | B44: 137.28226
...

Sheet Copy
A1: Sector | B1: Date | C1: Year | D1: Month | F1: Month Number | G1: Cereals and products | H1: Meat and fish | I1: Egg | J1: Milk and products | K1: Oils and fats | L1: Fruits | M1: Vegetables | N1: Pulses and products | O1: Sugar and Confectionery | P1: Spices | Q1: Non-alcoholic beverages | R1: Prepared meals, snacks, sweets etc. | S1: Food and beverages | T1: Pan, tobacco and intoxicants | U1: Clothing | V1: Footwear | W1: Clothing and footwear | X1: Housing | Y1: Fuel and light | Z1: Household goods and services | AA1: Health | AB1: Transport and communication | AC1: Recreation and amusement | AD1: Education | AE1: Personal care and effects | AF1: Miscellaneous | AG1: General index | AH1: Food | AI1: Energy | AJ1: Transportation | AK1: Education | AL1: Others | AM1: Flag
A2: Rural | B2: =DATE(C2,F2,1) -> 41275 | C2: 2013 | D2: January | E2: =_xlfn.CONCAT(TEXT(B2,"mmm"),,"-",RIGHT(C2,2)) -> Jan-13 | F2: =VLOOKUP(D2,'Problem Statement 4'!$G$2:$H$13,2,0) -> 1 | G2: 107.5 | H2: 106.3 | I2: 108.1 | J2: 104.9 | K2: 106.1 | L2: 103.9 | M2: 101.9 | N2: 106.1 | O2: 106.8 | P2: 103.1 | Q2: 104.8 | R2: 106.7 | S2: 105.5 | T2: 105.1 | U2: 106.5 | V2: 105.8 | W2: 106.4 | X2: 100.3 | Y2: 105.5 | Z2: 104.8 | AA2: 104 | AB2: 103.3 | AC2: 103.4 | AD2: 103.8 | AE2: 104.7 | AF2: 104 | AG2: 105.1 | AH2: =SUM(G2:S2) -> 1371.7 | AI2: =SUM(Y2) -> 105.5 | AJ2: =SUM(AB2) -> 103.3 | AK2: =SUM(AD2) -> 103.8 | AL2: =SUM(T2:X2,Z2:AA2,AC2,AE2:AF2) -> 1045 | AM2: =IF(AND(L2>150,M2>150),"Yes","No") -> No | AN2: =COUNTIFS(AM1:AM373,"Yes") -> 91
A3: Urban | B3: =DATE(C3,F3,1) -> 41275 | C3: 2013 | D3: January | E3: =_xlfn.CONCAT(TEXT(B3,"mmm"),,"-",RIGHT(C3,2)) -> Jan-13 | F3: =VLOOKUP(D3,'Problem Statement 4'!$G$2:$H$13,2,0) -> 1 | G3: 110.5 | H3: 109.1 | I3: 113 | J3: 103.6 | K3: 103.4 | L3: 102.3 | M3: 102.9 | N3: 105.8 | O3: 105.1 | P3: 101.8 | Q3: 105.1 | R3: 107.9 | S3: 105.9 | T3: 105.2 | U3: 105.9 | V3: 105 | W3: 105.8 | X3: 100.3 | Y3: 105.4 | Z3: 104.8 | AA3: 104.1 | AB3: 103.2 | AC3: 102.9 | AD3: 103.5 | AE3: 104.3 | AF3: 103.7 | AG3: 104 | AH3: =SUM(G3:S3) -> 1376.4 | AI3: =SUM(Y3) -> 105.4 | AJ3: =SUM(AB3) -> 103.2 | AK3: =SUM(AD3) -> 103.5 | AL3: =SUM(T3:X3,Z3:AA3,AC3,AE3:AF3) -> 1042 | AM3: =IF(AND(L3>150,M3>150),"Yes","No") -> No
A4: Rural+Urban | B4: =DATE(C4,F4,1) -> 41275 | C4: 2013 | D4: January | E4: =_xlfn.CONCAT(TEXT(B4,"mmm"),,"-",RIGHT(C4,2)) -> Jan-13 | F4: =VLOOKUP(D4,'Problem Statement 4'!$G$2:$H$13,2,0) -> 1 | G4: 108.4 | H4: 107.3 | I4: 110 | J4: 104.4 | K4: 105.1 | L4: 103.2 | M4: 102.2 | N4: 106 | O4: 106.2 | P4: 102.7 | Q4: 104.9 | R4: 107.3 | S4: 105.6 | T4: 105.1 | U4: 106.3 | V4: 105.5 | W4: 106.2 | X4: 100.3 | Y4: 105.5 | Z4: 104.8 | AA4: 104 | AB4: 103.2 | AC4: 103.1 | AD4: 103.6 | AE4: 104.5 | AF4: 103.9 | AG4: 104.6 | AH4: =SUM(G4:S4) -> 1373.3 | AI4: =SUM(Y4) -> 105.5 | AJ4: =SUM(AB4) -> 103.2 | AK4: =SUM(AD4) -> 103.6 | AL4: =SUM(T4:X4,Z4:AA4,AC4,AE4:AF4) -> 1043.7 | AM4: =IF(AND(L4>150,M4>150),"Yes","No") -> No
A5: Rural | B5: =DATE(C5,F5,1) -> 41306 | C5: 2013 | D5: February | E5: =_xlfn.CONCAT(TEXT(B5,"mmm"),,"-",RIGHT(C5,2)) -> Feb-13 | F5: =VLOOKUP(D5,'Problem Statement 4'!$G$2:$H$13,2,0) -> 2 | G5: 109.2 | H5: 108.7 | I5: 110.2 | J5: 105.4 | K5: 106.7 | L5: 104 | M5: 102.4 | N5: 105.9 | O5: 105.7 | P5: 103.1 | Q5: 105.1 | R5: 107.7 | S5: 106.3 | T5: 105.6 | U5: 107.1 | V5: 106.3 | W5: 107 | X5: 100.4 | Y5: 106.2 | Z5: 105.2 | AA5: 104.4 | AB5: 103.9 | AC5: 104 | AD5: 104.1 | AE5: 104.6 | AF5: 104.4 | AG5: 105.8 | AH5: =SUM(G5:S5) -> 1380.4 | AI5: =SUM(Y5) -> 106.2 | AJ5: =SUM(AB5) -> 103.9 | AK5: =SUM(AD5) -> 104.1 | AL5: =SUM(T5:X5,Z5:AA5,AC5,AE5:AF5) -> 1049 | AM5: =IF(AND(L5>150,M5>150),"Yes","No") -> No
A6: Urban | B6: =DATE(C6,F6,1) -> 41306 | C6: 2013 | D6: February | E6: =_xlfn.CONCAT(TEXT(B6,"mmm"),,"-",RIGHT(C6,2)) -> Feb-13 | F6: =VLOOKUP(D6,'Problem Statement 4'!$G$2:$H$13,2,0) -> 2 | G6: 112.9 | H6: 112.9 | I6: 116.9 | J6: 104 | K6: 103.5 | L6: 103.1 | M6: 104.9 | N6: 104.1 | O6: 103.8 | P6: 102.3 | Q6: 106 | R6: 109 | S6: 107.2 | T6: 106 | U6: 106.6 | V6: 105.5 | W6: 106.4 | X6: 100.4 | Y6: 105.7 | Z6: 105.2 | AA6: 104.7 | AB6: 104.4 | AC6: 103.3 | AD6: 103.7 | AE6: 104.3 | AF6: 104.3 | AG6: 104.7 | AH6: =SUM(G6:S6) -> 1390.6 | AI6: =SUM(Y6) -> 105.7 | AJ6: =SUM(AB6) -> 104.4 | AK6: =SUM(AD6) -> 103.7 | AL6: =SUM(T6:X6,Z6:AA6,AC6,AE6:AF6) -> 1046.7 | AM6: =IF(AND(L6>150,M6>150),"Yes","No") -> No
A7: Rural+Urban | B7: =DATE(C7,F7,1) -> 41306 | C7: 2013 | D7: February | E7: =_xlfn.CONCAT(TEXT(B7,"mmm"),,"-",RIGHT(C7,2)) -> Feb-13 | F7: =VLOOKUP(D7,'Problem Statement 4'!$G$2:$H$13,2,0) -> 2 | G7: 110.4 | H7: 110.2 | I7: 112.8 | J7: 104.9 | K7: 105.5 | L7: 103.6 | M7: 103.2 | N7: 105.3 | O7: 105.1 | P7: 102.8 | Q7: 105.5 | R7: 108.3 | S7: 106.6 | T7: 105.7 | U7: 106.9 | V7: 106 | W7: 106.8 | X7: 100.4 | Y7: 106 | Z7: 105.2 | AA7: 104.5 | AB7: 104.2 | AC7: 103.6 | AD7: 103.9 | AE7: 104.5 | AF7: 104.4 | AG7: 105.3 | AH7: =SUM(G7:S7) -> 1384.2 | AI7: =SUM(Y7) -> 106 | AJ7: =SUM(AB7) -> 104.2 | AK7: =SUM(AD7) -> 103.9 | AL7: =SUM(T7:X7,Z7:AA7,AC7,AE7:AF7) -> 1048 | AM7: =IF(AND(L7>150,M7>150),"Yes","No") -> No
A8: Rural | B8: =DATE(C8,F8,1) -> 41334 | C8: 2013 | D8: March | E8: =_xlfn.CONCAT(TEXT(B8,"mmm"),,"-",RIGHT(C8,2)) -> Mar-13 | F8: =VLOOKUP(D8,'Problem Statement 4'!$G$2:$H$13,2,0) -> 3 | G8: 110.2 | H8: 108.8 | I8: 109.9 | J8: 105.6 | K8: 106.2 | L8: 105.7 | M8: 101.4 | N8: 105.7 | O8: 105 | P8: 103.3 | Q8: 105.6 | R8: 108.2 | S8: 106.6 | T8: 106.5 | U8: 107.6 | V8: 106.8 | W8: 107.5 | X8: 100.4 | Y8: 106.1 | Z8: 105.6 | AA8: 104.7 | AB8: 104.6 | AC8: 104 | AD8: 104.3 | AE8: 104.3 | AF8: 104.6 | AG8: 106 | AH8: =SUM(G8:S8) -> 1382.2 | AI8: =SUM(Y8) -> 106.1 | AJ8: =SUM(AB8) -> 104.6 | AK8: =SUM(AD8) -> 104.3 | AL8: =SUM(T8:X8,Z8:AA8,AC8,AE8:AF8) -> 1052 | AM8: =IF(AND(L8>150,M8>150),"Yes","No") -> No
A9: Urban | B9: =DATE(C9,F9,1) -> 41334 | C9: 2013 | D9: March | E9: =_xlfn.CONCAT(TEXT(B9,"mmm"),,"-",RIGHT(C9,2)) -> Mar-13 | F9: =VLOOKUP(D9,'Problem Statement 4'!$G$2:$H$13,2,0) -> 3 | G9: 113.9 | H9: 111.4 | I9: 113.2 | J9: 104.3 | K9: 102.7 | L9: 104.9 | M9: 103.8 | N9: 103.5 | O9: 102.6 | P9: 102.4 | Q9: 107 | R9: 109.8 | S9: 107.3 | T9: 106.8 | U9: 107.2 | V9: 106 | W9: 107 | X9: 100.4 | Y9: 106 | Z9: 105.7 | AA9: 105.2 | AB9: 105.5 | AC9: 103.5 | AD9: 103.8 | AE9: 104.2 | AF9: 104.9 | AG9: 105 | AH9: =SUM(G9:S9) -> 1386.8 | AI9: =SUM(Y9) -> 106 | AJ9: =SUM(AB9) -> 105.5 | AK9: =SUM(AD9) -> 103.8 | AL9: =SUM(T9:X9,Z9:AA9,AC9,AE9:AF9) -> 1050.9 | AM9: =IF(AND(L9>150,M9>150),"Yes","No") -> No
A10: Rural+Urban | B10: =DATE(C10,F10,1) -> 41334 | C10: 2013 | D10: March | E10: =_xlfn.CONCAT(TEXT(B10,"mmm"),,"-",RIGHT(C10,2)) -> Mar-13 | F10: =VLOOKUP(D10,'Problem Statement 4'!$G$2:$H$13,2,0) -> 3 | G10: 111.4 | H10: 109.7 | I10: 111.2 | J10: 105.1 | K10: 104.9 | L10: 105.3 | M10: 102.2 | N10: 105 | O10: 104.2 | P10: 103 | Q10: 106.2 | R10: 108.9 | S10: 106.9 | T10: 106.6 | U10: 107.4 | V10: 106.5 | W10: 107.3 | X10: 100.4 | Y10: 106.1 | Z10: 105.6 | AA10: 104.9 | AB10: 105.1 | AC10: 103.7 | AD10: 104 | AE10: 104.3 | AF10: 104.7 | AG10: 105.5 | AH10: =SUM(G10:S10) -> 1384 | AI10: =SUM(Y10) -> 106.1 | AJ10: =SUM(AB10) -> 105.1 | AK10: =SUM(AD10) -> 104 | AL10: =SUM(T10:X10,Z10:AA10,AC10,AE10:AF10) -> 1051.4 | AM10: =IF(AND(L10>150,M10>150),"Yes","No") -> No
A11: Rural | B11: =DATE(C11,F11,1) -> 41365 | C11: 2013 | D11: April | E11: =_xlfn.CONCAT(TEXT(B11,"mmm"),,"-",RIGHT(C11,2)) -> Apr-13 | F11: =VLOOKUP(D11,'Problem Statement 4'!$G$2:$H$13,2,0) -> 4 | G11: 110.2 | H11: 109.5 | I11: 106.9 | J11: 106.3 | K11: 105.7 | L11: 108.3 | M11: 103.4 | N11: 105.7 | O11: 104.2 | P11: 103.2 | Q11: 106.5 | R11: 108.8 | S11: 107.1 | T11: 107.1 | U11: 108.1 | V11: 107.4 | W11: 108 | X11: 100.5 | Y11: 106.5 | Z11: 106.1 | AA11: 105.1 | AB11: 104.4 | AC11: 104.5 | AD11: 104.8 | AE11: 102.7 | AF11: 104.6 | AG11: 106.4 | AH11: =SUM(G11:S11) -> 1385.8 | AI11: =SUM(Y11) -> 106.5 | AJ11: =SUM(AB11) -> 104.4 | AK11: =SUM(AD11) -> 104.8 | AL11: =SUM(T11:X11,Z11:AA11,AC11,AE11:AF11) -> 1054.1 | AM11: =IF(AND(L11>150,M11>150),"Yes","No") -> No
A12: Urban | B12: =DATE(C12,F12,1) -> 41365 | C12: 2013 | D12: April | E12: =_xlfn.CONCAT(TEXT(B12,"mmm"),,"-",RIGHT(C12,2)) -> Apr-13 | F12: =VLOOKUP(D12,'Problem Statement 4'!$G$2:$H$13,2,0) -> 4 | G12: 114.6 | H12: 113.4 | I12: 106 | J12: 104.7 | K12: 102.1 | L12: 109.5 | M12: 109.7 | N12: 104.6 | O12: 102 | P12: 103.5 | Q12: 108.2 | R12: 110.6 | S12: 108.8 | T12: 108.5 | U12: 107.9 | V12: 106.4 | W12: 107.7 | X12: 100.5 | Y12: 106.4 | Z12: 106.5 | AA12: 105.7 | AB12: 105 | AC12: 104 | AD12: 105.2 | AE12: 103.2 | AF12: 105.1 | AG12: 105.7 | AH12: =SUM(G12:S12) -> 1397.7 | AI12: =SUM(Y12) -> 106.4 | AJ12: =SUM(AB12) -> 105 | AK12: =SUM(AD12) -> 105.2 | AL12: =SUM(T12:X12,Z12:AA12,AC12,AE12:AF12) -> 1055.5 | AM12: =IF(AND(L12>150,M12>150),"Yes","No") -> No
A13: Rural+Urban | B13: =DATE(C13,F13,1) -> 41365 | C13: 2013 | D13: April | E13: =_xlfn.CONCAT(TEXT(B13,"mmm"),,"-",RIGHT(C13,2)) -> Apr-13 | F13: =VLOOKUP(D13,'Problem Statement 4'!$G$2:$H$13,2,0) -> 4 | G13: 111.6 | H13: 110.9 | I13: 106.6 | J13: 105.7 | K13: 104.4 | L13: 108.9 | M13: 105.5 | N13: 105.3 | O13: 103.5 | P13: 103.3 | Q13: 107.2 | R13: 109.6 | S13: 107.7 | T13: 107.5 | U13: 108 | V13: 107 | W13: 107.9 | X13: 100.5 | Y13: 106.5 | Z13: 106.3 | AA13: 105.3 | AB13: 104.7 | AC13: 104.2 | AD13: 105 | AE13: 102.9 | AF13: 104.8 | AG13: 106.1 | AH13: =SUM(G13:S13) -> 1390.2 | AI13: =SUM(Y13) -> 106.5 | AJ13: =SUM(AB13) -> 104.7 | AK13: =SUM(AD13) -> 105 | AL13: =SUM(T13:X13,Z13:AA13,AC13,AE13:AF13) -> 1054.4 | AM13: =IF(AND(L13>150,M13>150),"Yes","No") -> No
A14: Rural | B14: =DATE(C14,F14,1) -> 41395 | C14: 2013 | D14: May | E14: =_xlfn.CONCAT(TEXT(B14,"mmm"),,"-",RIGHT(C14,2)) -> May-13 | F14: =VLOOKUP(D14,'Problem Statement 4'!$G$2:$H$13,2,0) -> 5 | G14: 110.9 | H14: 109.8 | I14: 105.9 | J14: 107.5 | K14: 105.3 | L14: 108.1 | M14: 107.3 | N14: 106.1 | O14: 103.7 | P14: 104 | Q14: 107.4 | R14: 109.9 | S14: 108.1 | T14: 108.1 | U14: 108.8 | V14: 107.9 | W14: 108.6 | X14: 100.5 | Y14: 107.5 | Z14: 106.8 | AA14: 105.7 | AB14: 104.1 | AC14: 105 | AD14: 105.5 | AE14: 102.1 | AF14: 104.8 | AG14: 107.2 | AH14: =SUM(G14:S14) -> 1394 | AI14: =SUM(Y14) -> 107.5 | AJ14: =SUM(AB14) -> 104.1 | AK14: =SUM(AD14) -> 105.5 | AL14: =SUM(T14:X14,Z14:AA14,AC14,AE14:AF14) -> 1058.3 | AM14: =IF(AND(L14>150,M14>150),"Yes","No") -> No
... A373: Rural+Urban | B373: =DATE(C373,F373,1) -> 45047 | C373: 2023 | D373: May | E373: =_xlfn.CONCAT(TEXT(B373,"mmm"),,"-",RIGHT(C373,2)) -> May-23 | F373: =VLOOKUP(D373,'Problem Statement 4'!$G$2:$H$13,2,0) -> 5 | G373: 173.7 | H373: 214.3 | I373: 173.2 | J373: 179.5 | K373: 170 | L373: 172.2 | M373: 161 | N373: 175.6 | O373: 122.7 | P373: 218 | Q373: 173.4 | R373: 194.2 | S373: 179.1 | T373: 201 | U373: 187.3 | V373: 179.7 | W373: 186.2 | X373: 175.6 | Y373: 182.8 | Z373: 175.2 | AA373: 185.7 | AB373: 164.8 | AC373: 171.2 | AD373: 177.1 | AE373: 185.2 | AF373: 175.7 | AG373: 179.1 | AH373: =SUM(G373:S373) -> 2306.9 | AI373: =SUM(Y373) -> 182.8 | AJ373: =SUM(AB373) -> 164.8 | AK373: =SUM(AD373) -> 177.1 | AL373: =SUM(T373:X373,Z373:AA373,AC373,AE373:AF373) -> 1822.8 | AM373: =IF(AND(L373>150,M373>150),"Yes","No") -> Yes
P378: =SUMIFS(P1:P373,A1:A373,"Urban",D1:D373,"December") -> 1481.2

Sheet Main Data
A1: Sector | B1: Date | C1: Year | D1: Month | F1: Month Number | G1: Cereals and products | H1: Meat and fish | I1: Egg | J1: Milk and products | K1: Oils and fats | L1: Fruits | M1: Vegetables | N1: Pulses and products | O1: Sugar and Confectionery | P1: Spices | Q1: Non-alcoholic beverages | R1: Prepared meals, snacks, sweets etc. | S1: Food and beverages | T1: Pan, tobacco and intoxicants | U1: Clothing | V1: Footwear | W1: Clothing and footwear | X1: Housing | Y1: Fuel and light | Z1: Household goods and services | AA1: Health | AB1: Transport and communication | AC1: Recreation and amusement | AD1: Education | AE1: Personal care and effects | AF1: Miscellaneous | AG1: General index | AH1: Food | AI1: Energy | AJ1: Transportation | AK1: Education | AL1: Others
A2: Rural | B2: =DATE(C2,F2,1) -> 41275 | C2: 2013 | D2: January | E2: =_xlfn.CONCAT(TEXT(B2,"mmm"),,"-",RIGHT(C2,2)) -> Jan-13 | F2: =VLOOKUP(D2,'Problem Statement 4'!$G$2:$H$13,2,0) -> 1 | G2: 107.5 | H2: 106.3 | I2: 108.1 | J2: 104.9 | K2: 106.1 | L2: 103.9 | M2: 101.9 | N2: 106.1 | O2: 106.8 | P2: 103.1 | Q2: 104.8 | R2: 106.7 | S2: 105.5 | T2: 105.1 | U2: 106.5 | V2: 105.8 | W2: 106.4 | X2: 100.3 | Y2: 105.5 | Z2: 104.8 | AA2: 104 | AB2: 103.3 | AC2: 103.4 | AD2: 103.8 | AE2: 104.7 | AF2: 104 | AG2: 105.1 | AH2: =SUM(G2:S2) -> 1371.7 | AI2: =SUM(Y2) -> 105.5 | AJ2: =SUM(AB2) -> 103.3 | AK2: =SUM(AD2) -> 103.8 | AL2: =SUM(T2:X2,Z2:AA2,AC2,AE2:AF2) -> 1045
A3: Urban | B3: =DATE(C3,F3,1) -> 41275 | C3: 2013 | D3: January | E3: =_xlfn.CONCAT(TEXT(B3,"mmm"),,"-",RIGHT(C3,2)) -> Jan-13 | F3: =VLOOKUP(D3,'Problem Statement 4'!$G$2:$H$13,2,0) -> 1 | G3: 110.5 | H3: 109.1 | I3: 113 | J3: 103.6 | K3: 103.4 | L3: 102.3 | M3: 102.9 | N3: 105.8 | O3: 105.1 | P3: 101.8 | Q3: 105.1 | R3: 107.9 | S3: 105.9 | T3: 105.2 | U3: 105.9 | V3: 105 | W3: 105.8 | X3: 100.3 | Y3: 105.4 | Z3: 104.8 | AA3: 104.1 | AB3: 103.2 | AC3: 102.9 | AD3: 103.5 | AE3: 104.3 | AF3: 103.7 | AG3: 104 | AH3: =SUM(G3:S3) -> 1376.4 | AI3: =SUM(Y3) -> 105.4 | AJ3: =SUM(AB3) -> 103.2 | AK3: =SUM(AD3) -> 103.5 | AL3: =SUM(T3:X3,Z3:AA3,AC3,AE3:AF3) -> 1042
A4: Rural+Urban | B4: =DATE(C4,F4,1) -> 41275 | C4: 2013 | D4: January | E4: =_xlfn.CONCAT(TEXT(B4,"mmm"),,"-",RIGHT(C4,2)) -> Jan-13 | F4: =VLOOKUP(D4,'Problem Statement 4'!$G$2:$H$13,2,0) -> 1 | G4: 108.4 | H4: 107.3 | I4: 110 | J4: 104.4 | K4: 105.1 | L4: 103.2 | M4: 102.2 | N4: 106 | O4: 106.2 | P4: 102.7 | Q4: 104.9 | R4: 107.3 | S4: 105.6 | T4: 105.1 | U4: 106.3 | V4: 105.5 | W4: 106.2 | X4: 100.3 | Y4: 105.5 | Z4: 104.8 | AA4: 104 | AB4: 103.2 | AC4: 103.1 | AD4: 103.6 | AE4: 104.5 | AF4: 103.9 | AG4: 104.6 | AH4: =SUM(G4:S4) -> 1373.3 | AI4: =SUM(Y4) -> 105.5 | AJ4: =SUM(AB4) -> 103.2 | AK4: =SUM(AD4) -> 103.6 | AL4: =SUM(T4:X4,Z4:AA4,AC4,AE4:AF4) -> 1043.7
A5: Rural | B5: =DATE(C5,F5,1) -> 41306 | C5: 2013 | D5: February | E5: =_xlfn.CONCAT(TEXT(B5,"mmm"),,"-",RIGHT(C5,2)) -> Feb-13 | F5: =VLOOKUP(D5,'Problem Statement 4'!$G$2:$H$13,2,0) -> 2 | G5: 109.2 | H5: 108.7 | I5: 110.2 | J5: 105.4 | K5: 106.7 | L5: 104 | M5: 102.4 | N5: 105.9 | O5: 105.7 | P5: 103.1 | Q5: 105.1 | R5: 107.7 | S5: 106.3 | T5: 105.6 | U5: 107.1 | V5: 106.3 | W5: 107 | X5: 100.4 | Y5: 106.2 | Z5: 105.2 | AA5: 104.4 | AB5: 103.9 | AC5: 104 | AD5: 104.1 | AE5: 104.6 | AF5: 104.4 | AG5: 105.8 | AH5: =SUM(G5:S5) -> 1380.4 | AI5: =SUM(Y5) -> 106.2 | AJ5: =SUM(AB5) -> 103.9 | AK5: =SUM(AD5) -> 104.1 | AL5: =SUM(T5:X5,Z5:AA5,AC5,AE5:AF5) -> 1049
A6: Urban | B6: =DATE(C6,F6,1) -> 41306 | C6: 2013 | D6: February | E6: =_xlfn.CONCAT(TEXT(B6,"mmm"),,"-",RIGHT(C6,2)) -> Feb-13 | F6: =VLOOKUP(D6,'Problem Statement 4'!$G$2:$H$13,2,0) -> 2 | G6: 112.9 | H6: 112.9 | I6: 116.9 | J6: 104 | K6: 103.5 | L6: 103.1 | M6: 104.9 | N6: 104.1 | O6: 103.8 | P6: 102.3 | Q6: 106 | R6: 109 | S6: 107.2 | T6: 106 | U6: 106.6 | V6: 105.5 | W6: 106.4 | X6: 100.4 | Y6: 105.7 | Z6: 105.2 | AA6: 104.7 | AB6: 104.4 | AC6: 103.3 | AD6: 103.7 | AE6: 104.3 | AF6: 104.3 | AG6: 104.7 | AH6: =SUM(G6:S6) -> 1390.6 | AI6: =SUM(Y6) -> 105.7 | AJ6: =SUM(AB6) -> 104.4 | AK6: =SUM(AD6) -> 103.7 | AL6: =SUM(T6:X6,Z6:AA6,AC6,AE6:AF6) -> 1046.7
A7: Rural+Urban | B7: =DATE(C7,F7,1) -> 41306 | C7: 2013 | D7: February | E7: =_xlfn.CONCAT(TEXT(B7,"mmm"),,"-",RIGHT(C7,2)) -> Feb-13 | F7: =VLOOKUP(D7,'Problem Statement 4'!$G$2:$H$13,2,0) -> 2 | G7: 110.4 | H7: 110.2 | I7: 112.8 | J7: 104.9 | K7: 105.5 | L7: 103.6 | M7: 103.2 | N7: 105.3 | O7: 105.1 | P7: 102.8 | Q7: 105.5 | R7: 108.3 | S7: 106.6 | T7: 105.7 | U7: 106.9 | V7: 106 | W7: 106.8 | X7: 100.4 | Y7: 106 | Z7: 105.2 | AA7: 104.5 | AB7: 104.2 | AC7: 103.6 | AD7: 103.9 | AE7: 104.5 | AF7: 104.4 | AG7: 105.3 | AH7: =SUM(G7:S7) -> 1384.2 | AI7: =SUM(Y7) -> 106 | AJ7: =SUM(AB7) -> 104.2 | AK7: =SUM(AD7) -> 103.9 | AL7: =SUM(T7:X7,Z7:AA7,AC7,AE7:AF7) -> 1048
A8: Rural | B8: =DATE(C8,F8,1) -> 41334 | C8: 2013 | D8: March | E8: =_xlfn.CONCAT(TEXT(B8,"mmm"),,"-",RIGHT(C8,2)) -> Mar-13 | F8: =VLOOKUP(D8,'Problem Statement 4'!$G$2:$H$13,2,0) -> 3 | G8: 110.2 | H8: 108.8 | I8: 109.9 | J8: 105.6 | K8: 106.2 | L8: 105.7 | M8: 101.4 | N8: 105.7 | O8: 105 | P8: 103.3 | Q8: 105.6 | R8: 108.2 | S8: 106.6 | T8: 106.5 | U8: 107.6 | V8: 106.8 | W8: 107.5 | X8: 100.4 | Y8: 106.1 | Z8: 105.6 | AA8: 104.7 | AB8: 104.6 | AC8: 104 | AD8: 104.3 | AE8: 104.3 | AF8: 104.6 | AG8: 106 | AH8: =SUM(G8:S8) -> 1382.2 | AI8: =SUM(Y8) -> 106.1 | AJ8: =SUM(AB8) -> 104.6 | AK8: =SUM(AD8) -> 104.3 | AL8: =SUM(T8:X8,Z8:AA8,AC8,AE8:AF8) -> 1052
A9: Urban | B9: =DATE(C9,F9,1) -> 41334 | C9: 2013 | D9: March | E9: =_xlfn.CONCAT(TEXT(B9,"mmm"),,"-",RIGHT(C9,2)) -> Mar-13 | F9: =VLOOKUP(D9,'Problem Statement 4'!$G$2:$H$13,2,0) -> 3 | G9: 113.9 | H9: 111.4 | I9: 113.2 | J9: 104.3 | K9: 102.7 | L9: 104.9 | M9: 103.8 | N9: 103.5 | O9: 102.6 | P9: 102.4 | Q9: 107 | R9: 109.8 | S9: 107.3 | T9: 106.8 | U9: 107.2 | V9: 106 | W9: 107 | X9: 100.4 | Y9: 106 | Z9: 105.7 | AA9: 105.2 | AB9: 105.5 | AC9: 103.5 | AD9: 103.8 | AE9: 104.2 | AF9: 104.9 | AG9: 105 | AH9: =SUM(G9:S9) -> 1386.8 | AI9: =SUM(Y9) -> 106 | AJ9: =SUM(AB9) -> 105.5 | AK9: =SUM(AD9) -> 103.8 | AL9: =SUM(T9:X9,Z9:AA9,AC9,AE9:AF9) -> 1050.9
A10: Rural+Urban | B10: =DATE(C10,F10,1) -> 41334 | C10: 2013 | D10: March | E10: =_xlfn.CONCAT(TEXT(B10,"mmm"),,"-",RIGHT(C10,2)) -> Mar-13 | F10: =VLOOKUP(D10,'Problem Statement 4'!$G$2:$H$13,2,0) -> 3 | G10: 111.4 | H10: 109.7 | I10: 111.2 | J10: 105.1 | K10: 104.9 | L10: 105.3 | M10: 102.2 | N10: 105 | O10: 104.2 | P10: 103 | Q10: 106.2 | R10: 108.9 | S10: 106.9 | T10: 106.6 | U10: 107.4 | V10: 106.5 | W10: 107.3 | X10: 100.4 | Y10: 106.1 | Z10: 105.6 | AA10: 104.9 | AB10: 105.1 | AC10: 103.7 | AD10: 104 | AE10: 104.3 | AF10: 104.7 | AG10: 105.5 | AH10: =SUM(G10:S10) -> 1384 | AI10: =SUM(Y10) -> 106.1 | AJ10: =SUM(AB10) -> 105.1 | AK10: =SUM(AD10) -> 104 | AL10: =SUM(T10:X10,Z10:AA10,AC10,AE10:AF10) -> 1051.4
A11: Rural | B11: =DATE(C11,F11,1) -> 41365 | C11: 2013 | D11: April | E11: =_xlfn.CONCAT(TEXT(B11,"mmm"),,"-",RIGHT(C11,2)) -> Apr-13 | F11: =VLOOKUP(D11,'Problem Statement 4'!$G$2:$H$13,2,0) -> 4 | G11: 110.2 | H11: 109.5 | I11: 106.9 | J11: 106.3 | K11: 105.7 | L11: 108.3 | M11: 103.4 | N11: 105.7 | O11: 104.2 | P11: 103.2 | Q11: 106.5 | R11: 108.8 | S11: 107.1 | T11: 107.1 | U11: 108.1 | V11: 107.4 | W11: 108 | X11: 100.5 | Y11: 106.5 | Z11: 106.1 | AA11: 105.1 | AB11: 104.4 | AC11: 104.5 | AD11: 104.8 | AE11: 102.7 | AF11: 104.6 | AG11: 106.4 | AH11: =SUM(G11:S11) -> 1385.8 | AI11: =SUM(Y11) -> 106.5 | AJ11: =SUM(AB11) -> 104.4 | AK11: =SUM(AD11) -> 104.8 | AL11: =SUM(T11:X11,Z11:AA11,AC11,AE11:AF11) -> 1054.1
A12: Urban | B12: =DATE(C12,F12,1) -> 41365 | C12: 2013 | D12: April | E12: =_xlfn.CONCAT(TEXT(B12,"mmm"),,"-",RIGHT(C12,2)) -> Apr-13 | F12: =VLOOKUP(D12,'Problem Statement 4'!$G$2:$H$13,2,0) -> 4 | G12: 114.6 | H12: 113.4 | I12: 106 | J12: 104.7 | K12: 102.1 | L12: 109.5 | M12: 109.7 | N12: 104.6 | O12: 102 | P12: 103.5 | Q12: 108.2 | R12: 110.6 | S12: 108.8 | T12: 108.5 | U12: 107.9 | V12: 106.4 | W12: 107.7 | X12: 100.5 | Y12: 106.4 | Z12: 106.5 | AA12: 105.7 | AB12: 105 | AC12: 104 | AD12: 105.2 | AE12: 103.2 | AF12: 105.1 | AG12: 105.7 | AH12: =SUM(G12:S12) -> 1397.7 | AI12: =SUM(Y12) -> 106.4 | AJ12: =SUM(AB12) -> 105 | AK12: =SUM(AD12) -> 105.2 | AL12: =SUM(T12:X12,Z12:AA12,AC12,AE12:AF12) -> 1055.5
A13: Rural+Urban | B13: =DATE(C13,F13,1) -> 41365 | C13: 2013 | D13: April | E13: =_xlfn.CONCAT(TEXT(B13,"mmm"),,"-",RIGHT(C13,2)) -> Apr-13 | F13: =VLOOKUP(D13,'Problem Statement 4'!$G$2:$H$13,2,0) -> 4 | G13: 111.6 | H13: 110.9 | I13: 106.6 | J13: 105.7 | K13: 104.4 | L13: 108.9 | M13: 105.5 | N13: 105.3 | O13: 103.5 | P13: 103.3 | Q13: 107.2 | R13: 109.6 | S13: 107.7 | T13: 107.5 | U13: 108 | V13: 107 | W13: 107.9 | X13: 100.5 | Y13: 106.5 | Z13: 106.3 | AA13: 105.3 | AB13: 104.7 | AC13: 104.2 | AD13: 105 | AE13: 102.9 | AF13: 104.8 | AG13: 106.1 | AH13: =SUM(G13:S13) -> 1390.2 | AI13: =SUM(Y13) -> 106.5 | AJ13: =SUM(AB13) -> 104.7 | AK13: =SUM(AD13) -> 105 | AL13: =SUM(T13:X13,Z13:AA13,AC13,AE13:AF13) -> 1054.4
... A373: Rural+Urban | B373: =DATE(C373,F373,1) -> 45047 | C373: 2023 | D373: May | E373: =_xlfn.CONCAT(TEXT(B373,"mmm"),,"-",RIGHT(C373,2)) -> May-23 | F373: =VLOOKUP(D373,'Problem Statement 4'!$G$2:$H$13,2,0) -> 5 | G373: 173.7 | H373: 214.3 | I373: 173.2 | J373: 179.5 | K373: 170 | L373: 172.2 | M373: 161 | N373: 175.6 | O373: 122.7 | P373: 218 | Q373: 173.4 | R373: 194.2 | S373: 179.1 | T373: 201 | U373: 187.3 | V373: 179.7 | W373: 186.2 | X373: 175.6 | Y373: 182.8 | Z373: 175.2 | AA373: 185.7 | AB373: 164.8 | AC373: 171.2 | AD373: 177.1 | AE373: 185.2 | AF373: 175.7 | AG373: 179.1 | AH373: =SUM(G373:S373) -> 2306.9 | AI373: =SUM(Y373) -> 182.8 | AJ373: =SUM(AB373) -> 164.8 | AK373: =SUM(AD373) -> 177.1 | AL373: =SUM(T373:X373,Z373:AA373,AC373,AE373:AF373) -> 1822.8

Sheet Sheet2
A1: 1 | B1: State the business problem in one or two sentences. | E1: Here are the Excel-ready recommendation points for the insight:
B2: The business problem is to analyze the key drivers and trends of inflation in India by examining the Consumer Price Index (CPI) data across various categories, identify the main contributors to rising prices, and assess the impact of major events such as COVID-19 and global oil price fluctuations on overall inflation. This analysis will help policymakers and businesses understand inflation dynamics and make informed decisions.
E3: "Oil price changes have a strong impact on overall inflation and all major CPI categories in India."
A5: 2 | B5: Data Preparation – Briefly explain how you ensured clean, accurate data.
E7: 📊 Excel Table: Recommendations for Oil-Driven Inflation
B8: Handle Missing Values: Identify missing data points and use imputation techniques like moving averages to fill gaps. For example, if April’s value is missing, average March and May’s values to estimate it.
B9: Check for Duplicates: Remove any duplicate records to avoid skewed results. | E9: Recommendation # | F9: Recommendation
B10: Standardize Formats: Ensure all dates, categories, and numerical values follow a consistent format (e.g., YYYY-MM for dates). | E10: 1 | F10: Diversify energy mix with renewables to reduce dependency on imported crude oil
B11: Validate Data Ranges: Check that index values are within expected ranges and flag any outliers for review. | E11: 2 | F11: Strengthen strategic petroleum reserves to buffer against global price shocks
B12: Categorize Data: Group items correctly into broader categories (food, energy, etc.) as per the CPI basket. | E12: 3 | F12: Implement dynamic fuel pricing to smooth consumer impact during oil price swings
B13: Document Changes: Keep a log of all cleaning steps for transparency and reproducibility. | E13: 4 | F13: Promote fuel-efficient transport and logistics through EVs and optimized routing
E14: 5 | F14: Encourage modal shifts (rail, waterways) to reduce fuel intensity in freight
E15: 6 | F15: Expand domestic refining capacity to reduce import costs and improve resilience
E16: 7 | F16: Use targeted subsidies or direct transfers during fuel-driven inflation spikes
E17: 8 | F17: Improve CPI granularity to monitor fuel-linked inflation across categories
A19: 3 | B19: Analysis Approach – Describe the charts, formulas, and metrics you used.
E20: Let me know if you'd like this formatted with slicers, conditional formatting, or integrated into a CPI dashboard.
B21: I used SUMIFS and AVERAGEIFS formulas in Excel to aggregate and analyze data for different categories and time periods.
B22: The Inflation Rate was calculated using the formula:
B23: [(\text{Current Value} - \text{Previous Value}) / \text{Previous Value} \times 100]
B24: This was applied for year-on-year (YoY), month-on-month (MoM), and quarter-on-quarter (QoQ) calculations.
B25: For visualization, I used:
B26: Bar charts to compare inflation rates across categories and time periods.
B27: Pie charts to show the contribution of each category to overall inflation.
B28: Line charts to display trends in inflation over time.
B29: Combo charts to compare multiple metrics (e.g., category-wise inflation and overall CPI) in a single view.
B30: These charts and metrics helped identify which month, year, or category had the highest or lowest inflation.
B31: Also used slicers for better analysis of the data
A34: 4 | B34: Key Insights – Highlight the most important findings from your analysis.
B35: The highest inflation was observed in the food category during the year 2020, likely due to supply chain disruptions and increased demand during the COVID-19 pandemic.
B36: In 2021, the energy category experienced the highest CPI inflation, possibly driven by global crude oil price hikes and increased fuel costs.
B37: The transportation category also saw its highest CPI inflation in 2021, correlating with rising fuel prices and increased transportation costs post-pandemic.
B38: Top Contributing Category: Food often has the highest contribution to the CPI basket, meaning changes in food prices have the biggest impact on overall inflation. For example, if food prices rise sharply, overall inflation increases significantly.
B39: Year with Highest Inflation: The analysis may show that a specific year (e.g., 2022) had the highest year-on-year inflation, possibly due to global supply chain disruptions or spikes in commodity prices.
B40: COVID-19 Impact: After March 2020, inflation in healthcare and essential goods increased, reflecting higher demand and supply challenges during the pandemic.
B41: Food Price Trends: Within the last 12 months, certain months (e.g., July 2022) saw the highest food inflation, often driven by items like vegetables or edible oils.
B42: Oil Price Influence: Fluctuations in global crude oil prices from 2021-2023 directly affected fuel and transportation costs, which in turn pushed up overall inflation.
B43: Urban vs. Rural: CPI-U (urban) and CPI-R (rural) may show different inflation patterns, highlighting varying impacts on city and village consumers.
A49: 5 | B49: Creative Recommendations – Suggest actions based on your insights.
B50: Based on the CPI inflation analysis, here are some creative recommendations:
...

Sheet Insights
A6: CPI INFLATION CASE STUDY ANALYSIS
A7: The main aim is to analyze the key drivers and trends of inflation in India by examining the Consumer Price Index (CPI) data across various categories, identify the main contributors to rising prices, and assess the impact of major events such as COVID-19 and global oil price fluctuations on overall inflation. This analysis will help policymakers and businesses understand inflation dynamics and make informed decisions.
A13: Key Insights 1) 2020 – Highest inflation in food category due to COVID-19-related supply chain disruptions and increased demand 2) 2021 – Energy category saw highest CPI inflation driven by global crude oil price hikes and fuel costs 3) 2021 – Transportation category also peaked due to rising fuel prices and post-pandemic logistics costs 4) Food is the top contributing category in CPI; sharp food price increases significantly impact overall inflation 5) 2022 – Likely the year with highest overall inflation due to global supply chain disruptions and commodity spikes 6) Post-March 2020 – Healthcare and essential goods inflation rose due to pandemic-driven demand and supply challenges 7) July 2022 – Highest food inflation observed, especially in vegetables and edible oils 8) 2021–2023 – Crude oil price fluctuations directly impacted fuel and transportation costs, pushing up inflation 9) Oil price changes have a strong impact on overall inflation and all major CPI categories in India | C13: 1. 2020 – Food Inflation Surge (COVID Impact) | M13: 2. 2021 – Energy Inflation (Oil Price Spike) | V13: 3. 2021 – Transportation Inflation (Fuel & Logistics)
D33: 5. 2022 – Peak Overall Inflation (Global Disruptions) | M33: 6. Precovid and post covid Inflation Trends across all the Categories
W34: YOY CORRELATION WITH OIL PRICES (2021-2023) | AA34: MOM CORRELATION WITH OIL PRICES (2021-2023)
P40: Problem State,ent 4 and 5
A51: Recommendations
A53: 1)Targeted Subsidies – Offer subsidies or tax relief on food and fuel to reduce consumer burden during inflation spikes
A54: 2)Diversify Imports – Reduce dependence on volatile oil markets by diversifying energy imports and investing in renewables
A55: 3)Strengthen Supply Chains – Improve logistics and support local producers to stabilize prices, especially post-COVID
A56: 4)Monitor and Regulate Hoarding – Prevent artificial price hikes in high-inflation categories like food through stricter monitoring
A57: 5)Promote Urban-Rural Balance – Tailor inflation policies to address distinct CPI-U (urban) and CPI-R (rural) inflation patterns
A58: 6)Public Awareness – Educate consumers on inflation trends and encourage smart spending and saving habits
A59: 7)Data-Driven Policy – Use real-time CPI data to inform timely decisions like interest rate changes or trade adjustments
A64: Footer: Complete
A65: Dataset : CPI Inflation Data set
A66: Time period -October - November 2025

Sheet Sheet8
A2: 🎬 Opening
A4: "Inflation is not just a number—it’s a story of how everyday lives are impacted by changing prices. By analyzing CPI data across categories, we can trace how global events like COVID-19 and oil price shocks ripple through households and businesses, shaping decisions for policymakers and industries alike."
A6: 🧩 Step 1: Understanding the Data
A8: The dataset covers rural and urban cities, tracking both year-on-year (YoY) and month-on-month (MoM) price fluctuations.
A9: To simplify analysis, categories were grouped into Food, Transportation, Energy, Education, and Others.
A11: 📊 Step 2: Insights Across Time
A13: 2020 – The Food Shock
A15: COVID-19 disrupted supply chains and increased demand for essentials.
A16: Result: Food inflation surged across both rural and urban areas.
A17: This was the first major spike, highlighting how crises directly affect basic needs.
A19: 2021 – The Energy Wave
A21: As economies reopened, fuel and oil prices climbed sharply.
... A50: In Precovid and post covid data comparision I got that all the major inflation was observed in Food transportation and energy rest education and other categories remained unimpacted

Sheet Crude oil
A1: Month | B1: Indian Basket of Crude Oil (USD/Barrel) | C1: General index | D1: Food | E1: Energy | F1: Transportation | G1: Education | H1: Others
A2: Jan-21 | B2: 54.79 | C2: =INDEX(Sheet2!$E$83:$AL$109, MATCH('Crude oil'!$A2, Sheet2!$E$83:$E$109, 0), MATCH('Crude oil'!C$1, Sheet2!$E$83:$AL$83, 0)) -> #N/A | D2: =INDEX(Sheet2!$E$83:$AL$109, MATCH('Crude oil'!$A2, Sheet2!$E$83:$E$109, 0), MATCH('Crude oil'!D$1, Sheet2!$E$83:$AL$83, 0)) -> #N/A | E2: =INDEX(Sheet2!$E$83:$AL$109, MATCH('Crude oil'!$A2, Sheet2!$E$83:$E$109, 0), MATCH('Crude oil'!E$1, Sheet2!$E$83:$AL$83, 0)) -> #N/A | F2: =INDEX(Sheet2!$E$83:$AL$109, MATCH('Crude oil'!$A2, Sheet2!$E$83:$E$109, 0), MATCH('Crude oil'!F$1, Sheet2!$E$83:$AL$83, 0)) -> #N/A | G2: =INDEX(Sheet2!$E$83:$AL$109, MATCH('Crude oil'!$A2, Sheet2!$E$83:$E$109, 0), MATCH('Crude oil'!G$1, Sheet2!$E$83:$AL$83, 0)) -> #N/A | H2: =INDEX(Sheet2!$E$83:$AL$109, MATCH('Crude oil'!$A2, Sheet2!$E$83:$E$109, 0), MATCH('Crude oil'!H$1, Sheet2!$E$83:$AL$83, 0)) -> #N/A
A3: Feb-21 | B3: 61.22 | C3: =INDEX(Sheet2!$E$83:$AL$109, MATCH('Crude oil'!$A3, Sheet2!$E$83:$E$109, 0), MATCH('Crude oil'!C$1, Sheet2!$E$83:$AL$83, 0)) -> #N/A | D3: =INDEX(Sheet2!$E$83:$AL$109, MATCH('Crude oil'!$A3, Sheet2!$E$83:$E$109, 0), MATCH('Crude oil'!D$1, Sheet2!$E$83:$AL$83, 0)) -> #N/A | E3: =INDEX(Sheet2!$E$83:$AL$109, MATCH('Crude oil'!$A3, Sheet2!$E$83:$E$109, 0), MATCH('Crude oil'!E$1, Sheet2!$E$83:$AL$83, 0)) -> #N/A | F3: =INDEX(Sheet2!$E$83:$AL$109, MATCH('Crude oil'!$A3, Sheet2!$E$83:$E$109, 0), MATCH('Crude oil'!F$1, Sheet2!$E$83:$AL$83, 0)) -> #N/A | G3: =INDEX(Sheet2!$E$83:$AL$109, MATCH('Crude oil'!$A3, Sheet2!$E$83:$E$109, 0), MATCH('Crude oil'!G$1, Sheet2!$E$83:$AL$83, 0)) -> #N/A | H3: =INDEX(Sheet2!$E$83:$AL$109, MATCH('Crude oil'!$A3, Sheet2!$E$83:$E$109, 0), MATCH('Crude oil'!H$1, Sheet2!$E$83:$AL$83, 0)) -> #N/A
A4: Mar-21 | B4: 64.73 | C4: =INDEX(Sheet2!$E$83:$AL$109, MATCH('Crude oil'!$A4, Sheet2!$E$83:$E$109, 0), MATCH('Crude oil'!C$1, Sheet2!$E$83:$AL$83, 0)) -> 156.8 | D4: =INDEX(Sheet2!$E$83:$AL$109, MATCH('Crude oil'!$A4, Sheet2!$E$83:$E$109, 0), MATCH('Crude oil'!D$1, Sheet2!$E$83:$AL$83, 0)) -> 2039.4 | E4: =INDEX(Sheet2!$E$83:$AL$109, MATCH('Crude oil'!$A4, Sheet2!$E$83:$E$109, 0), MATCH('Crude oil'!E$1, Sheet2!$E$83:$AL$83, 0)) -> 155.5 | F4: =INDEX(Sheet2!$E$83:$AL$109, MATCH('Crude oil'!$A4, Sheet2!$E$83:$E$109, 0), MATCH('Crude oil'!F$1, Sheet2!$E$83:$AL$83, 0)) -> 146.2 | G4: =INDEX(Sheet2!$E$83:$AL$109, MATCH('Crude oil'!$A4, Sheet2!$E$83:$E$109, 0), MATCH('Crude oil'!G$1, Sheet2!$E$83:$AL$83, 0)) -> 160.2 | H4: =INDEX(Sheet2!$E$83:$AL$109, MATCH('Crude oil'!$A4, Sheet2!$E$83:$E$109, 0), MATCH('Crude oil'!H$1, Sheet2!$E$83:$AL$83, 0)) -> 1583.2
A5: Apr-21 | B5: 63.4 | C5: =INDEX(Sheet2!$E$83:$AL$109, MATCH('Crude oil'!$A5, Sheet2!$E$83:$E$109, 0), MATCH('Crude oil'!C$1, Sheet2!$E$83:$AL$83, 0)) -> 157.8 | D5: =INDEX(Sheet2!$E$83:$AL$109, MATCH('Crude oil'!$A5, Sheet2!$E$83:$E$109, 0), MATCH('Crude oil'!D$1, Sheet2!$E$83:$AL$83, 0)) -> 2064.1 | E5: =INDEX(Sheet2!$E$83:$AL$109, MATCH('Crude oil'!$A5, Sheet2!$E$83:$E$109, 0), MATCH('Crude oil'!E$1, Sheet2!$E$83:$AL$83, 0)) -> 155.6 | F5: =INDEX(Sheet2!$E$83:$AL$109, MATCH('Crude oil'!$A5, Sheet2!$E$83:$E$109, 0), MATCH('Crude oil'!F$1, Sheet2!$E$83:$AL$83, 0)) -> 146.6 | G5: =INDEX(Sheet2!$E$83:$AL$109, MATCH('Crude oil'!$A5, Sheet2!$E$83:$E$109, 0), MATCH('Crude oil'!G$1, Sheet2!$E$83:$AL$83, 0)) -> 160.3 | H5: =INDEX(Sheet2!$E$83:$AL$109, MATCH('Crude oil'!$A5, Sheet2!$E$83:$E$109, 0), MATCH('Crude oil'!H$1, Sheet2!$E$83:$AL$83, 0)) -> 1591.9
A6: May-21 | B6: 66.95 | C6: =INDEX(Sheet2!$E$83:$AL$109, MATCH('Crude oil'!$A6, Sheet2!$E$83:$E$109, 0), MATCH('Crude oil'!C$1, Sheet2!$E$83:$AL$83, 0)) -> 160.4 | D6: =INDEX(Sheet2!$E$83:$AL$109, MATCH('Crude oil'!$A6, Sheet2!$E$83:$E$109, 0), MATCH('Crude oil'!D$1, Sheet2!$E$83:$AL$83, 0)) -> 2105.7 | E6: =INDEX(Sheet2!$E$83:$AL$109, MATCH('Crude oil'!$A6, Sheet2!$E$83:$E$109, 0), MATCH('Crude oil'!E$1, Sheet2!$E$83:$AL$83, 0)) -> 159.4 | F6: =INDEX(Sheet2!$E$83:$AL$109, MATCH('Crude oil'!$A6, Sheet2!$E$83:$E$109, 0), MATCH('Crude oil'!F$1, Sheet2!$E$83:$AL$83, 0)) -> 148.9 | G6: =INDEX(Sheet2!$E$83:$AL$109, MATCH('Crude oil'!$A6, Sheet2!$E$83:$E$109, 0), MATCH('Crude oil'!G$1, Sheet2!$E$83:$AL$83, 0)) -> 161.2 | H6: =INDEX(Sheet2!$E$83:$AL$109, MATCH('Crude oil'!$A6, Sheet2!$E$83:$E$109, 0), MATCH('Crude oil'!H$1, Sheet2!$E$83:$AL$83, 0)) -> 1619.5
A7: Jun-21 | B7: 71.98 | C7: =INDEX(Sheet2!$E$83:$AL$109, MATCH('Crude oil'!$A7, Sheet2!$E$83:$E$109, 0), MATCH('Crude oil'!C$1, Sheet2!$E$83:$AL$83, 0)) -> 161.3 | D7: =INDEX(Sheet2!$E$83:$AL$109, MATCH('Crude oil'!$A7, Sheet2!$E$83:$E$109, 0), MATCH('Crude oil'!D$1, Sheet2!$E$83:$AL$83, 0)) -> 2133.9 | E7: =INDEX(Sheet2!$E$83:$AL$109, MATCH('Crude oil'!$A7, Sheet2!$E$83:$E$109, 0), MATCH('Crude oil'!E$1, Sheet2!$E$83:$AL$83, 0)) -> 159.8 | F7: =INDEX(Sheet2!$E$83:$AL$109, MATCH('Crude oil'!$A7, Sheet2!$E$83:$E$109, 0), MATCH('Crude oil'!F$1, Sheet2!$E$83:$AL$83, 0)) -> 150.7 | G7: =INDEX(Sheet2!$E$83:$AL$109, MATCH('Crude oil'!$A7, Sheet2!$E$83:$E$109, 0), MATCH('Crude oil'!G$1, Sheet2!$E$83:$AL$83, 0)) -> 161.7 | H7: =INDEX(Sheet2!$E$83:$AL$109, MATCH('Crude oil'!$A7, Sheet2!$E$83:$E$109, 0), MATCH('Crude oil'!H$1, Sheet2!$E$83:$AL$83, 0)) -> 1618.4
A8: Jul-21 | B8: 73.54 | C8: =INDEX(Sheet2!$E$83:$AL$109, MATCH('Crude oil'!$A8, Sheet2!$E$83:$E$109, 0), MATCH('Crude oil'!C$1, Sheet2!$E$83:$AL$83, 0)) -> 162.5 | D8: =INDEX(Sheet2!$E$83:$AL$109, MATCH('Crude oil'!$A8, Sheet2!$E$83:$E$109, 0), MATCH('Crude oil'!D$1, Sheet2!$E$83:$AL$83, 0)) -> 2147 | E8: =INDEX(Sheet2!$E$83:$AL$109, MATCH('Crude oil'!$A8, Sheet2!$E$83:$E$109, 0), MATCH('Crude oil'!E$1, Sheet2!$E$83:$AL$83, 0)) -> 160.7 | F8: =INDEX(Sheet2!$E$83:$AL$109, MATCH('Crude oil'!$A8, Sheet2!$E$83:$E$109, 0), MATCH('Crude oil'!F$1, Sheet2!$E$83:$AL$83, 0)) -> 153.1 | G8: =INDEX(Sheet2!$E$83:$AL$109, MATCH('Crude oil'!$A8, Sheet2!$E$83:$E$109, 0), MATCH('Crude oil'!G$1, Sheet2!$E$83:$AL$83, 0)) -> 163.2 | H8: =INDEX(Sheet2!$E$83:$AL$109, MATCH('Crude oil'!$A8, Sheet2!$E$83:$E$109, 0), MATCH('Crude oil'!H$1, Sheet2!$E$83:$AL$83, 0)) -> 1627.2
A9: Aug-21 | B9: 69.8 | C9: =INDEX(Sheet2!$E$83:$AL$109, MATCH('Crude oil'!$A9, Sheet2!$E$83:$E$109, 0), MATCH('Crude oil'!C$1, Sheet2!$E$83:$AL$83, 0)) -> 163.2 | D9: =INDEX(Sheet2!$E$83:$AL$109, MATCH('Crude oil'!$A9, Sheet2!$E$83:$E$109, 0), MATCH('Crude oil'!D$1, Sheet2!$E$83:$AL$83, 0)) -> 2142 | E9: =INDEX(Sheet2!$E$83:$AL$109, MATCH('Crude oil'!$A9, Sheet2!$E$83:$E$109, 0), MATCH('Crude oil'!E$1, Sheet2!$E$83:$AL$83, 0)) -> 162.6 | F9: =INDEX(Sheet2!$E$83:$AL$109, MATCH('Crude oil'!$A9, Sheet2!$E$83:$E$109, 0), MATCH('Crude oil'!F$1, Sheet2!$E$83:$AL$83, 0)) -> 154 | G9: =INDEX(Sheet2!$E$83:$AL$109, MATCH('Crude oil'!$A9, Sheet2!$E$83:$E$109, 0), MATCH('Crude oil'!G$1, Sheet2!$E$83:$AL$83, 0)) -> 163.8 | H9: =INDEX(Sheet2!$E$83:$AL$109, MATCH('Crude oil'!$A9, Sheet2!$E$83:$E$109, 0), MATCH('Crude oil'!H$1, Sheet2!$E$83:$AL$83, 0)) -> 1640.7
A10: Sep-21 | B10: 73.13 | C10: =INDEX(Sheet2!$E$83:$AL$109, MATCH('Crude oil'!$A10, Sheet2!$E$83:$E$109, 0), MATCH('Crude oil'!C$1, Sheet2!$E$83:$AL$83, 0)) -> 163.2 | D10: =INDEX(Sheet2!$E$83:$AL$109, MATCH('Crude oil'!$A10, Sheet2!$E$83:$E$109, 0), MATCH('Crude oil'!D$1, Sheet2!$E$83:$AL$83, 0)) -> 2142 | E10: =INDEX(Sheet2!$E$83:$AL$109, MATCH('Crude oil'!$A10, Sheet2!$E$83:$E$109, 0), MATCH('Crude oil'!E$1, Sheet2!$E$83:$AL$83, 0)) -> 162.6 | F10: =INDEX(Sheet2!$E$83:$AL$109, MATCH('Crude oil'!$A10, Sheet2!$E$83:$E$109, 0), MATCH('Crude oil'!F$1, Sheet2!$E$83:$AL$83, 0)) -> 154 | G10: =INDEX(Sheet2!$E$83:$AL$109, MATCH('Crude oil'!$A10, Sheet2!$E$83:$E$109, 0), MATCH('Crude oil'!G$1, Sheet2!$E$83:$AL$83, 0)) -> 163.7 | H10: =INDEX(Sheet2!$E$83:$AL$109, MATCH('Crude oil'!$A10, Sheet2!$E$83:$E$109, 0), MATCH('Crude oil'!H$1, Sheet2!$E$83:$AL$83, 0)) -> 1641
A11: Oct-21 | B11: 82.11 | C11: =INDEX(Sheet2!$E$83:$AL$109, MATCH('Crude oil'!$A11, Sheet2!$E$83:$E$109, 0), MATCH('Crude oil'!C$1, Sheet2!$E$83:$AL$83, 0)) -> 165.5 | D11: =INDEX(Sheet2!$E$83:$AL$109, MATCH('Crude oil'!$A11, Sheet2!$E$83:$E$109, 0), MATCH('Crude oil'!D$1, Sheet2!$E$83:$AL$83, 0)) -> 2175.5 | E11: =INDEX(Sheet2!$E$83:$AL$109, MATCH('Crude oil'!$A11, Sheet2!$E$83:$E$109, 0), MATCH('Crude oil'!E$1, Sheet2!$E$83:$AL$83, 0)) -> 164.2 | F11: =INDEX(Sheet2!$E$83:$AL$109, MATCH('Crude oil'!$A11, Sheet2!$E$83:$E$109, 0), MATCH('Crude oil'!F$1, Sheet2!$E$83:$AL$83, 0)) -> 155.7 | G11: =INDEX(Sheet2!$E$83:$AL$109, MATCH('Crude oil'!$A11, Sheet2!$E$83:$E$109, 0), MATCH('Crude oil'!G$1, Sheet2!$E$83:$AL$83, 0)) -> 163.9 | H11: =INDEX(Sheet2!$E$83:$AL$109, MATCH('Crude oil'!$A11, Sheet2!$E$83:$E$109, 0), MATCH('Crude oil'!H$1, Sheet2!$E$83:$AL$83, 0)) -> 1650.5
A12: Nov-21 | B12: 80.64 | C12: =INDEX(Sheet2!$E$83:$AL$109, MATCH('Crude oil'!$A12, Sheet2!$E$83:$E$109, 0), MATCH('Crude oil'!C$1, Sheet2!$E$83:$AL$83, 0)) -> 166.7 | D12: =INDEX(Sheet2!$E$83:$AL$109, MATCH('Crude oil'!$A12, Sheet2!$E$83:$E$109, 0), MATCH('Crude oil'!D$1, Sheet2!$E$83:$AL$83, 0)) -> 2194.1 | E12: =INDEX(Sheet2!$E$83:$AL$109, MATCH('Crude oil'!$A12, Sheet2!$E$83:$E$109, 0), MATCH('Crude oil'!E$1, Sheet2!$E$83:$AL$83, 0)) -> 163.9 | F12: =INDEX(Sheet2!$E$83:$AL$109, MATCH('Crude oil'!$A12, Sheet2!$E$83:$E$109, 0), MATCH('Crude oil'!F$1, Sheet2!$E$83:$AL$83, 0)) -> 154.8 | G12: =INDEX(Sheet2!$E$83:$AL$109, MATCH('Crude oil'!$A12, Sheet2!$E$83:$E$109, 0), MATCH('Crude oil'!G$1, Sheet2!$E$83:$AL$83, 0)) -> 164.3 | H12: =INDEX(Sheet2!$E$83:$AL$109, MATCH('Crude oil'!$A12, Sheet2!$E$83:$E$109, 0), MATCH('Crude oil'!H$1, Sheet2!$E$83:$AL$83, 0)) -> 1660.1
A13: Dec-21 | B13: 73.3 | C13: =INDEX(Sheet2!$E$83:$AL$109, MATCH('Crude oil'!$A13, Sheet2!$E$83:$E$109, 0), MATCH('Crude oil'!C$1, Sheet2!$E$83:$AL$83, 0)) -> 166.2 | D13: =INDEX(Sheet2!$E$83:$AL$109, MATCH('Crude oil'!$A13, Sheet2!$E$83:$E$109, 0), MATCH('Crude oil'!D$1, Sheet2!$E$83:$AL$83, 0)) -> 2180.9 | E13: =INDEX(Sheet2!$E$83:$AL$109, MATCH('Crude oil'!$A13, Sheet2!$E$83:$E$109, 0), MATCH('Crude oil'!E$1, Sheet2!$E$83:$AL$83, 0)) -> 164.1 | F13: =INDEX(Sheet2!$E$83:$AL$109, MATCH('Crude oil'!$A13, Sheet2!$E$83:$E$109, 0), MATCH('Crude oil'!F$1, Sheet2!$E$83:$AL$83, 0)) -> 155.7 | G13: =INDEX(Sheet2!$E$83:$AL$109, MATCH('Crude oil'!$A13, Sheet2!$E$83:$E$109, 0), MATCH('Crude oil'!G$1, Sheet2!$E$83:$AL$83, 0)) -> 164.4 | H13: =INDEX(Sheet2!$E$83:$AL$109, MATCH('Crude oil'!$A13, Sheet2!$E$83:$E$109, 0), MATCH('Crude oil'!H$1, Sheet2!$E$83:$AL$83, 0)) -> 1666
... A27: Feb-23 | B27: 82.28 | C27: =INDEX(Sheet2!$E$83:$AL$109, MATCH('Crude oil'!$A27, Sheet2!$E$83:$E$109, 0), MATCH('Crude oil'!C$1, Sheet2!$E$83:$AL$83, 0)) -> 177.2 | D27: =INDEX(Sheet2!$E$83:$AL$109, MATCH('Crude oil'!$A27, Sheet2!$E$83:$E$109, 0), MATCH('Crude oil'!D$1, Sheet2!$E$83:$AL$83, 0)) -> 2279.1 | E27: =INDEX(Sheet2!$E$83:$AL$109, MATCH('Crude oil'!$A27, Sheet2!$E$83:$E$109, 0), MATCH('Crude oil'!E$1, Sheet2!$E$83:$AL$83, 0)) -> 182.1 | F27: =INDEX(Sheet2!$E$83:$AL$109, MATCH('Crude oil'!$A27, Sheet2!$E$83:$E$109, 0), MATCH('Crude oil'!F$1, Sheet2!$E$83:$AL$83, 0)) -> 164.2 | G27: =INDEX(Sheet2!$E$83:$AL$109, MATCH('Crude oil'!$A27, Sheet2!$E$83:$E$109, 0), MATCH('Crude oil'!G$1, Sheet2!$E$83:$AL$83, 0)) -> 175 | H27: =INDEX(Sheet2!$E$83:$AL$109, MATCH('Crude oil'!$A27, Sheet2!$E$83:$E$109, 0), MATCH('Crude oil'!H$1, Sheet2!$E$83:$AL$83, 0)) -> 1807

Sheet Sheet1
A1: Cereals and products | D1: Food:
A2: Meat and fish
A3: Egg | D3: Cereals and products
A4: Milk and products | D4: Meat and fish
A5: Oils and fats | D5: Egg
A6: Fruits | D6: Milk and products
A7: Vegetables | D7: Oils and fats
A8: Pulses and products | D8: Fruits
A9: Sugar and Confectionery | D9: Vegetables
A10: Spices | D10: Pulses and products
A11: Non-alcoholic beverages | D11: Sugar and Confectionery
A12: Prepared meals, snacks, sweets etc. | D12: Spices
A13: Food and beverages | D13: Non-alcoholic beverages
A14: Pan, tobacco and intoxicants | D14: Prepared meals, snacks, sweets etc.
A15: Clothing | D15: Food and beverages
A16: Footwear
A17: Clothing and footwear | D17: Energy:
A18: Housing
A19: Fuel and light | D19: Fuel and light
A20: Household goods and services
A21: Health | D21: Transportation:
A22: Transport and communication
A23: Recreation and amusement | D23: Transport (from "Transport and communication," only the transport part)
A24: Education
A25: Personal care and effects | D25: Other:
A26: Miscellaneous
D27: Pan, tobacco and intoxicants
D28: Clothing
D29: Footwear
D30: Clothing and footwear
D31: Housing
D32: Household goods and services
D33: Health
D34: Recreation and amusement
D35: Education
D36: Personal care and effects
D37: Miscellaneous
B64: Data Analysis Tasks: | D64: To analyze year-on-year (Y-o-Y) CPI growth since 2017 and find the year with the highest inflation, follow these steps:
B66: Find which category (e.g., food or energy) contributed most to inflation in the latest month. | D66: 1. Collect Data:
B67: Analyze year-on-year CPI growth since 2017 and identify the year with the highest inflation (e.g., 2020 due to COVID-19).
...

Sheet Sheet3
A1: Sector | B1: Year | C1: Month | D1: Cereals and products | E1: Meat and fish | F1: Egg | G1: Milk and products | H1: Oils and fats | I1: Fruits | J1: Vegetables | K1: Pulses and products | L1: Sugar and Confectionery | M1: Spices | N1: Non-alcoholic beverages | O1: Prepared meals, snacks, sweets etc. | P1: Food and beverages | Q1: Pan, tobacco and intoxicants | R1: Clothing | S1: Footwear | T1: Clothing and footwear | U1: Housing | V1: Fuel and light | W1: Household goods and services | X1: Health | Y1: Transport and communication | Z1: Recreation and amusement | AA1: Education | AB1: Personal care and effects | AC1: Miscellaneous | AD1: General index | AE1: Food | AF1: Energy | AG1: Transportation | AH1: Education | AI1: Others
A2: Rural | B2: 2023 | C2: January | D2: 174 | E2: 208.3 | F2: 192.9 | G2: 174.3 | H2: 192.6 | I2: 156.3 | J2: 142.9 | K2: 170.7 | L2: 120.3 | M2: 210.5 | N2: 176.9 | O2: 188.5 | P2: 175 | Q2: 196.9 | R2: 189 | S2: 186.3 | T2: 188.6 | U2: 172.1 | V2: 183.2 | W2: 177.2 | X2: 184.7 | Y2: 168.2 | Z2: 171.8 | AA2: 177.8 | AB2: 178.4 | AC2: 176.5 | AD2: 177.8 | AE2: 2283.2 | AF2: 183.2 | AG2: 168.2 | AH2: 177.8 | AI2: 1821.5
A3: Urban | B3: 2023 | C3: January | D3: 173.3 | E3: 215.2 | F3: 197 | G3: 175.2 | H3: 178 | I3: 160.5 | J3: 175.3 | K3: 171.2 | L3: 122.7 | M3: 204.3 | N3: 163.7 | O3: 194.3 | P3: 179.5 | Q3: 201.6 | R3: 178.7 | S3: 165.3 | T3: 176.6 | U3: 172.1 | V3: 180.1 | W3: 168 | X3: 178.5 | Y3: 159.5 | Z3: 167.8 | AA3: 171.8 | AB3: 178.8 | AC3: 168.9 | AD3: 174.9 | AE3: 2310.2 | AF3: 180.1 | AG3: 159.5 | AH3: 171.8 | AI3: 1756.3
A4: Rural+Urban | B4: 2023 | C4: January | D4: 173.8 | E4: 210.7 | F4: 194.5 | G4: 174.6 | H4: 187.2 | I4: 158.3 | J4: 153.9 | K4: 170.9 | L4: 121.1 | M4: 208.4 | N4: 171.4 | O4: 191.2 | P4: 176.7 | Q4: 198.2 | R4: 184.9 | S4: 177.6 | T4: 183.8 | U4: 172.1 | V4: 182 | W4: 172.9 | X4: 182.3 | Y4: 163.6 | Z4: 169.5 | AA4: 174.3 | AB4: 178.6 | AC4: 172.8 | AD4: 176.5 | AE4: 2292.7 | AF4: 182 | AG4: 163.6 | AH4: 174.3 | AI4: 1792.7
A5: Rural | B5: 2023 | C5: February | D5: 174.2 | E5: 205.2 | F5: 173.9 | G5: 177 | H5: 183.4 | I5: 167.2 | J5: 140.9 | K5: 170.4 | L5: 119.1 | M5: 212.1 | N5: 177.6 | O5: 189.9 | P5: 174.8 | Q5: 198.3 | R5: 190 | S5: 187 | T5: 189.6 | U5: 173.5 | V5: 181.6 | W5: 178.6 | X5: 186.6 | Y5: 169 | Z5: 172.8 | AA5: 178.5 | AB5: 180.7 | AC5: 177.9 | AD5: 178 | AE5: 2265.7 | AF5: 181.6 | AG5: 169 | AH5: 178.5 | AI5: 1835
A6: Urban | B6: 2023 | C6: February | D6: 174.7 | E6: 212.2 | F6: 177.2 | G6: 177.9 | H6: 172.2 | I6: 172.1 | J6: 175.8 | K6: 172.2 | L6: 121.9 | M6: 204.8 | N6: 164.9 | O6: 196.6 | P6: 180.7 | Q6: 202.7 | R6: 180.3 | S6: 167 | T6: 178.2 | U6: 173.5 | V6: 182.8 | W6: 169.2 | X6: 180.8 | Y6: 159.8 | Z6: 168.4 | AA6: 172.5 | AB6: 181.4 | AC6: 170 | AD6: 176.3 | AE6: 2303.2 | AF6: 182.8 | AG6: 159.8 | AH6: 172.5 | AI6: 1771.5
A7: Rural+Urban | B7: 2023 | C7: February | D7: 174.4 | E7: 207.7 | F7: 175.2 | G7: 177.3 | H7: 179.3 | I7: 169.5 | J7: 152.7 | K7: 171 | L7: 120 | M7: 209.7 | N7: 172.3 | O7: 193 | P7: 177 | Q7: 199.5 | R7: 186.2 | S7: 178.7 | T7: 185.1 | U7: 173.5 | V7: 182.1 | W7: 174.2 | X7: 184.4 | Y7: 164.2 | Z7: 170.3 | AA7: 175 | AB7: 181 | AC7: 174.1 | AD7: 177.2 | AE7: 2279.1 | AF7: 182.1 | AG7: 164.2 | AH7: 175 | AI7: 1807
A8: Rural | B8: 2023 | C8: March | D8: 174.3 | E8: 205.2 | F8: 173.9 | G8: 177 | H8: 183.3 | I8: 167.2 | J8: 140.9 | K8: 170.5 | L8: 119.1 | M8: 212.1 | N8: 177.6 | O8: 189.9 | P8: 174.8 | Q8: 198.4 | R8: 190 | S8: 187 | T8: 189.6 | U8: 173.5 | V8: 181.4 | W8: 178.6 | X8: 186.6 | Y8: 169 | Z8: 172.8 | AA8: 178.5 | AB8: 180.7 | AC8: 177.9 | AD8: 178 | AE8: 2265.8 | AF8: 181.4 | AG8: 169 | AH8: 178.5 | AI8: 1835.1
A9: Urban | B9: 2023 | C9: March | D9: 174.7 | E9: 212.2 | F9: 177.2 | G9: 177.9 | H9: 172.2 | I9: 172.1 | J9: 175.9 | K9: 172.2 | L9: 121.9 | M9: 204.8 | N9: 164.9 | O9: 196.6 | P9: 180.8 | Q9: 202.7 | R9: 180.2 | S9: 167 | T9: 178.2 | U9: 173.5 | V9: 182.6 | W9: 169.2 | X9: 180.8 | Y9: 159.8 | Z9: 168.4 | AA9: 172.5 | AB9: 181.5 | AC9: 170 | AD9: 176.3 | AE9: 2303.4 | AF9: 182.6 | AG9: 159.8 | AH9: 172.5 | AI9: 1771.5
A10: Rural+Urban | B10: 2023 | C10: March | D10: 174.4 | E10: 207.7 | F10: 175.2 | G10: 177.3 | H10: 179.2 | I10: 169.5 | J10: 152.8 | K10: 171.1 | L10: 120 | M10: 209.7 | N10: 172.3 | O10: 193 | P10: 177 | Q10: 199.5 | R10: 186.1 | S10: 178.7 | T10: 185.1 | U10: 173.5 | V10: 181.9 | W10: 174.2 | X10: 184.4 | Y10: 164.2 | Z10: 170.3 | AA10: 175 | AB10: 181 | AC10: 174.1 | AD10: 177.2 | AE10: 2279.2 | AF10: 181.9 | AG10: 164.2 | AH10: 175 | AI10: 1806.9
A11: Rural | B11: 2023 | C11: April | D11: 173.3 | E11: 206.9 | F11: 167.9 | G11: 178.2 | H11: 178.5 | I11: 173.7 | J11: 142.8 | K11: 172.8 | L11: 120.4 | M11: 215.5 | N11: 178.2 | O11: 190.5 | P11: 175.5 | Q11: 199.5 | R11: 190.7 | S11: 187.3 | T11: 190.2 | U11: 175.2 | V11: 181.5 | W11: 179.1 | X11: 187.2 | Y11: 169.4 | Z11: 173.2 | AA11: 179.4 | AB11: 183.8 | AC11: 178.9 | AD11: 178.8 | AE11: 2274.2 | AF11: 181.5 | AG11: 169.4 | AH11: 179.4 | AI11: 1845.1
A12: Urban | B12: 2023 | C12: April | D12: 174.8 | E12: 213.7 | F12: 172.4 | G12: 178.8 | H12: 168.7 | I12: 179.2 | J12: 179.9 | K12: 174.7 | L12: 123.1 | M12: 207.8 | N12: 165.5 | O12: 197 | P12: 182.1 | Q12: 203.5 | R12: 181 | S12: 167.7 | T12: 178.9 | U12: 175.2 | V12: 182.1 | W12: 169.6 | X12: 181.5 | Y12: 160.1 | Z12: 168.8 | AA12: 174.2 | AB12: 184.4 | AC12: 170.9 | AD12: 177.4 | AE12: 2317.7 | AF12: 182.1 | AG12: 160.1 | AH12: 174.2 | AI12: 1781.5
A13: Rural+Urban | B13: 2023 | C13: April | D13: 173.8 | E13: 209.3 | F13: 169.6 | G13: 178.4 | H13: 174.9 | I13: 176.3 | J13: 155.4 | K13: 173.4 | L13: 121.3 | M13: 212.9 | N13: 172.9 | O13: 193.5 | P13: 177.9 | Q13: 200.6 | R13: 186.9 | S13: 179.2 | T13: 185.7 | U13: 175.2 | V13: 181.7 | W13: 174.6 | X13: 185 | Y13: 164.5 | Z13: 170.7 | AA13: 176.4 | AB13: 184 | AC13: 175 | AD13: 178.1 | AE13: 2289.6 | AF13: 181.7 | AG13: 164.5 | AH13: 176.4 | AI13: 1816.9
... A16: Rural+Urban | B16: 2023 | C16: May | D16: 173.7 | E16: 214.3 | F16: 173.2 | G16: 179.5 | H16: 170 | I16: 172.2 | J16: 161 | K16: 175.6 | L16: 122.7 | M16: 218 | N16: 173.4 | O16: 194.2 | P16: 179.1 | Q16: 201 | R16: 187.3 | S16: 179.7 | T16: 186.2 | U16: 175.6 | V16: 182.8 | W16: 175.2 | X16: 185.7 | Y16: 164.8 | Z16: 171.2 | AA16: 177.1 | AB16: 185.2 | AC16: 175.7 | AD16: 179.1 | AE16: 2306.9 | AF16: 182.8 | AG16: 164.8 | AH16: 177.1 | AI16: 1822.8

Sheet Problem Statement 1
B1: 2023
A2: Category | B2: January | C2: February | D2: March | E2: April | F2: May | G2: Total | H2: Percentage
